Workbook

Sheet README
A1: BRAZIL | CHIKV SEROLOGY
A2: Primary evidence inventory | Search cutoff 10 September 2026 | v1.0
A4: Primary papers | G4: =COUNTA(Sources!A5:A26) -> 22
A5: Sample-site-timepoint records | G5: =COUNTA(Survey_units!A5:A40) -> 36
A6: Assay / endpoint rows | G6: =COUNTA(Raw_observations!A5:A60) -> 56
A7: Rows with directly reported numerator + denominator | G7: =COUNT(Raw_observations!I5:I60) -> 46
A8: Age-specific raw strata | G8: =COUNTA(Age_strata!A5:A19) -> 15
A9: UFs with at least one extracted observation | G9: =COUNTIF(UF_coverage!D5:D31,">0") -> 9
A11: WHAT THIS FILE CONTAINS
A12: Observed Brazilian human serology values traced from primary publications. Cortes-Azuero (2025/2026) and Kang (2024) were starting points; complementary searching extends to 2026-09-10. Values are aggregate observations, NOT published FOI/S estimates and NOT individual participant data.
A15: IMPORTANT COMPLETENESS LIMIT
A16: This is a targeted, partially verified source inventory. The exact Cortes 12-study input table and the Kang extraction supplement could not be fully retrieved. Eight Brazilian primary citations from the Kang bibliography were traced. Do not call this a complete export of either study or an exhaustive systematic review.
A19: START HERE
A20: Priority_view: readable survey inventory. Raw_observations: all measured endpoints. Survey_units: place/date/population. Age_strata: recovered age counts. Sources and Review_trace: provenance. Gaps_exclusions: actions before modelling.
A23: DO NOT POOL EVERY ROW
A24: Several records are the same persons at repeated visits, the same sera tested for IgG/IgM, or pooled totals of listed sub-sites. Use cohort_or_overlap_id and preferred_endpoint_within_sample. None is assumed to represent a whole Brazilian state.
A27: RAW VS REPORTED
A28: Green numbers are imported observations. Black formula percentages are n_positive/n_tested. Reported percentages and confidence intervals are preserved separately. Blank counts mean not recovered, not zero. No numerator was reverse-engineered from a rounded/weighted percentage.
A31: WHAT CHANGES FOR YOUR PROJECT
A32: Evidence extends beyond Juazeiro and Quixada, including local city/household surveys, low-prevalence samples and longitudinal cohorts. This expands calibration options, but it does not supply representative serology for every UF/year. Match geography, ages, dates and assay before use.
... A48: Review local-population records first; retrieve missing numerators and exact sampling frames; complete seed-paper crosswalk. Use design-aware uncertainty and a serological observation model rather than treating every published prevalence as a binomial state-level estimate.

Sheet Priority_view
A1: Priority view
A2: One selected endpoint per sample/site/timepoint. NOT 36 independent surveys. Use roles and cohort IDs; exact counts are separate from reported estimates.
A4: survey_id | B4: source_id | C4: uf | D4: place | E4: collection_dates | F4: population | G4: endpoint | H4: n_tested | I4: n_positive | J4: raw_proportion | K4: reported_proportion | L4: reported_ci_low | M4: reported_ci_high | N4: suggested_role | O4: raw_count_status | P4: repeated_or_pooled_id | Q4: publication | R4: source_url
A5: U01 | B5: P01 | C5: BA | D5: Feira de Santana / George Americo | E5: Abstract: Oct-Dec 2015; methods: Nov-Dec 2015; table caption: 2015-2016 | F5: Residents of selected epidemic hotspots | G5: IgM or IgG | H5: 385 | I5: 220 | J5: =IF(OR(H5="",I5="",H5=0),"",I5/H5) -> 0.57142857 | K5: 0.571 | N5: LOCAL_CONTEXT | O5: DIRECT n/N | P5: DIAS_2015_U01 | Q5: Dias 2018 | R5: https://wwwnc.cdc.gov/eid/article/24/4/17-1370_article
A6: U02 | B6: P01 | C6: BA | D6: Riachao do Jacuipe / Alto do Cemiterio | E6: Abstract: Oct-Dec 2015; methods: Nov-Dec 2015; table caption: 2015-2016 | F6: Residents of selected epidemic hotspots | G6: IgM or IgG | H6: 446 | I6: 204 | J6: =IF(OR(H6="",I6="",H6=0),"",I6/H6) -> 0.4573991 | K6: 0.457 | N6: LOCAL_CONTEXT | O6: DIRECT n/N | P6: DIAS_2015_U02 | Q6: Dias 2018 | R6: https://wwwnc.cdc.gov/eid/article/24/4/17-1370_article
A7: U03 | B7: P02 | C7: BA | D7: Chapada rural district, Riachao do Jacuipe | E7: April 2016 | F7: Rural residents | G7: IgM or IgG | H7: 120 | I7: 24 | J7: =IF(OR(H7="",I7="",H7=0),"",I7/H7) -> 0.2 | K7: 0.2 | L7: 0.154 | M7: 0.357 | N7: LOCAL_POPULATION_PRIORITY | O7: DIRECT n/N | P7: CUNHA_CHAPADA | Q7: Cunha 2017 | R7: https://journals.plos.org/plosntds/article?id=10.1371/journal.pntd.0005319
A8: U04 | B8: P03 | C8: BA | D8: Pau da Lima, Salvador | E8: November 2016-February 2017 | F8: Residents in three contiguous valleys | G8: IgG | H8: 1772 | I8: 209 | J8: =IF(OR(H8="",I8="",H8=0),"",I8/H8) -> 0.11794582 | K8: 0.118 | L8: 0.098 | M8: 0.137 | N8: LOCAL_CONTEXT | O8: DIRECT n/N | P8: ANJOS_PAU_DA_LIMA | Q8: Anjos 2020 | R8: https://wwwnc.cdc.gov/eid/article/26/7/19-0846_article
A9: U05 | B9: P04 | C9: CE | D9: Juazeiro do Norte | E9: June-December 2018 | F9: Urban household residents | G9: IgM or IgG | H9: 404 | I9: 103 | J9: =IF(OR(H9="",I9="",H9=0),"",I9/H9) -> 0.2549505 | K9: 0.255 | N9: LOCAL_POPULATION_PRIORITY | O9: DIRECT n/N | P9: BARRETO_JUAZEIRO | Q9: Barreto 2020 | R9: https://link.springer.com/article/10.1186/s12879-020-05611-5
A10: U06 | B10: P05 | C10: CE | D10: Quixada | E10: 2019 (title); exact months not recovered | F10: Endemic-area residents | G10: Anti-CHIKV exposure; marker combination not verified | H10: 409 | J10: =IF(OR(H10="",I10="",H10=0),"",I10/H10) | K10: 0.707 | N10: LOCAL_CONTEXT | O10: Numerator NOT retrieved; do not reconstruct from rounded % | P10: BRAGA_QUIXADA | Q10: Braga 2021 | R10: https://onlinelibrary.wiley.com/doi/abs/10.1111/zph.12888
A11: U07 | B11: P06 | C11: PE | D11: Fulni-o, Aguas Belas / Itaiba | E11: Aug 2016 and Jun 2017; pooled | F11: PAI cardiovascular cohort adults | G11: IgG | H11: 272 | I11: 213 | J11: =IF(OR(H11="",I11="",H11=0),"",I11/H11) -> 0.78308824 | K11: 0.783 | L11: 0.729 | M11: 0.831 | N11: LOCAL_CONTEXT | O11: DIRECT n/N | P11: NICACIO_U07 | Q11: Nicacio 2021 | R11: https://journals.plos.org/plosntds/article?id=10.1371/journal.pntd.0009468
A12: U08 | B12: P06 | C12: PE | D12: Truka, Cabrobo | E12: June 2017 | F12: PAI cardiovascular cohort adults | G12: IgG | H12: 109 | I12: 0 | J12: =IF(OR(H12="",I12="",H12=0),"",I12/H12) -> 0 | K12: 0 | N12: LOCAL_CONTEXT | O12: DIRECT n/N | P12: NICACIO_U08 | Q12: Nicacio 2021 | R12: https://journals.plos.org/plosntds/article?id=10.1371/journal.pntd.0009468
A13: U09 | B13: P06 | C13: BA | D13: Juazeiro urban non-Indigenous comparison | E13: June 2017 | F13: PAI cardiovascular cohort adults | G13: IgG | H13: 52 | I13: 3 | J13: =IF(OR(H13="",I13="",H13=0),"",I13/H13) -> 0.057692308 | K13: 0.058 | L13: 0.0121 | M13: 0.16 | N13: LOCAL_CONTEXT | O13: DIRECT n/N | P13: NICACIO_U09 | Q13: Nicacio 2021 | R13: https://journals.plos.org/plosntds/article?id=10.1371/journal.pntd.0009468
A14: U10 | B14: P07 | C14: RJ | D14: Rio de Janeiro city | E14: July-October 2018 | F14: City residents | G14: IgM or IgG | H14: 2120 | I14: 371 | J14: =IF(OR(H14="",I14="",H14=0),"",I14/H14) -> 0.175 | K14: 0.18 | L14: 0.148 | M14: 0.212 | N14: LOCAL_POPULATION_PRIORITY | O14: DIRECT n/N | P14: PERISSE_RIO | Q14: Perisse 2020 | R14: https://journals.plos.org/plosone/article?id=10.1371/journal.pone.0243239
A15: U11 | B15: P08 | C15: AC | D15: Cruzeiro do Sul | E15: July 2015-June 2016 | F15: Pregnant women | G15: IgG | H15: 435 | I15: 41 | J15: =IF(OR(H15="",I15="",H15=0),"",I15/H15) -> 0.094252874 | K15: 0.094 | N15: RESTRICTED_POPULATION | O15: DIRECT n/N | P15: KANUNFRE_U11 | Q15: Kanunfre 2022 | R15: https://pmc.ncbi.nlm.nih.gov/articles/PMC8993149/
A16: U12 | B16: P08 | C16: AC | D16: Cruzeiro do Sul | E16: July 2015-June 2016 | F16: Unrelated newborns | G16: IgG | H16: 642 | I16: 66 | J16: =IF(OR(H16="",I16="",H16=0),"",I16/H16) -> 0.10280374 | K16: 0.103 | N16: EXCLUDE_INFANT_INFECTION | O16: DIRECT n/N | P16: KANUNFRE_U12 | Q16: Kanunfre 2022 | R16: https://pmc.ncbi.nlm.nih.gov/articles/PMC8993149/
A17: U13 | B17: P09 | C17: BA | D17: Feira de Santana, 30 sentinel areas | E17: Apr-Sep 2017 in tables; 2016/2017 in abstract | F17: Urban residents across living-condition strata | G17: IgM or IgG | H17: 1981 | J17: =IF(OR(H17="",I17="",H17=0),"",I17/H17) | K17: 0.221 | L17: 0.167 | M17: 0.286 | N17: LOCAL_POPULATION_PRIORITY | O17: Numerator NOT retrieved; do not reconstruct from rounded % | P17: TEIXEIRA_FEIRA | Q17: Teixeira 2021 | R17: https://journals.plos.org/plosntds/article?id=10.1371/journal.pntd.0009289
A18: U14 | B18: P10 | C18: PE | D18: Recife | E18: August 2018-February 2019 | F18: Household residents | G18: IgM or IgG | H18: 2070 | I18: 770 | J18: =IF(OR(H18="",I18="",H18=0),"",I18/H18) -> 0.37198068 | K18: 0.372 | L18: 0.34 | M18: 0.404 | N18: LOCAL_POPULATION_PRIORITY | O18: DIRECT n/N | P18: BRAGA_RECIFE | Q18: Braga 2023 | R18: https://journals.plos.org/plosntds/article?id=10.1371/journal.pntd.0011270
A19: U15 | B19: P11 | C19: DF | D19: Sao Sebastiao administrative region, Federal District | E19: Feb-Mar 2020 and Oct 2020-Jan 2021; pooled | F19: Residents sampled from households | G19: IgM or IgG | H19: 1405 | J19: =IF(OR(H19="",I19="",H19=0),"",I19/H19) | K19: 0.054 | L19: 0.044 | M19: 0.067 | N19: LOCAL_POPULATION_PRIORITY | O19: Numerator NOT retrieved; do not reconstruct from rounded % | P19: NOBRE_DF | Q19: Nobre 2025 | R19: https://link.springer.com/article/10.1186/s12879-025-10516-2
A20: U16 | B20: P12 | C20: AP | D20: Macapa / HEMOAP | E20: 2015 | F20: Volunteer blood donors | G20: IgG | H20: 442 | I20: 1 | J20: =IF(OR(H20="",I20="",H20=0),"",I20/H20) -> 0.0022624434 | K20: 0.002 | N20: RESTRICTED_POPULATION | O20: DIRECT n/N | P20: SLAVOV_U16 | Q20: Slavov 2018 | R20: https://pubmed.ncbi.nlm.nih.gov/30370414/
A21: U17 | B21: P12 | C21: SP | D21: Ribeirao Preto blood centre | E21: 2016 | F21: Volunteer blood donors | G21: IgG | H21: 455 | I21: 0 | J21: =IF(OR(H21="",I21="",H21=0),"",I21/H21) -> 0 | K21: 0 | N21: RESTRICTED_POPULATION | O21: DIRECT n/N | P21: SLAVOV_U17 | Q21: Slavov 2018 | R21: https://pubmed.ncbi.nlm.nih.gov/30370414/
A22: U18 | B22: P13 | C22: DF | D22: Federal District blood donors | E22: Early 2019 outbreak | F22: Volunteer blood donors | G22: IgG | H22: 450 | I22: 4 | J22: =IF(OR(H22="",I22="",H22=0),"",I22/H22) -> 0.0088888889 | K22: 0.0089 | N22: RESTRICTED_POPULATION | O22: DIRECT n/N | P22: MENDES_DF | Q22: Silva Mendes 2022 | R22: https://onlinelibrary.wiley.com/doi/10.1111/tme.12870
A23: U19 | B23: P14 | C23: BA | D23: Alto do Cabrito, Salvador | E23: March-October 2018 | F23: Residents in four informal settlements | G23: IgG | H23: 376 | I23: 23 | J23: =IF(OR(H23="",I23="",H23=0),"",I23/H23) -> 0.061170213 | K23: 0.061 | N23: LOCAL_CONTEXT | O23: DIRECT n/N | P23: TRAVIS_SALVADOR | Q23: Travis 2025 | R23: https://pmc.ncbi.nlm.nih.gov/articles/PMC12440227/
A24: U20 | B24: P14 | C24: BA | D24: Marechal Rondon, Salvador | E24: March-October 2018 | F24: Residents in four informal settlements | G24: IgG | H24: 337 | I24: 16 | J24: =IF(OR(H24="",I24="",H24=0),"",I24/H24) -> 0.047477745 | K24: 0.048 | N24: LOCAL_CONTEXT | O24: DIRECT n/N | P24: TRAVIS_SALVADOR | Q24: Travis 2025 | R24: https://pmc.ncbi.nlm.nih.gov/articles/PMC12440227/
A25: U21 | B25: P14 | C25: BA | D25: Nova Constituinte, Salvador | E25: March-October 2018 | F25: Residents in four informal settlements | G25: IgG | H25: 305 | I25: 69 | J25: =IF(OR(H25="",I25="",H25=0),"",I25/H25) -> 0.22622951 | K25: 0.226 | N25: LOCAL_CONTEXT | O25: DIRECT n/N | P25: TRAVIS_SALVADOR | Q25: Travis 2025 | R25: https://pmc.ncbi.nlm.nih.gov/articles/PMC12440227/
A26: U22 | B26: P14 | C26: BA | D26: Rio Sena, Salvador | E26: March-October 2018 | F26: Residents in four informal settlements | G26: IgG | H26: 298 | I26: 13 | J26: =IF(OR(H26="",I26="",H26=0),"",I26/H26) -> 0.043624161 | K26: 0.043 | N26: LOCAL_CONTEXT | O26: DIRECT n/N | P26: TRAVIS_SALVADOR | Q26: Travis 2025 | R26: https://pmc.ncbi.nlm.nih.gov/articles/PMC12440227/
A27: U23 | B27: P14 | C27: BA | D27: Four Salvador communities pooled | E27: March-October 2018 | F27: Residents in four informal settlements | G27: IgG | H27: 1316 | I27: 121 | J27: =IF(OR(H27="",I27="",H27=0),"",I27/H27) -> 0.091945289 | K27: 0.092 | N27: POOLED_DUPLICATE | O27: DIRECT n/N | P27: TRAVIS_SALVADOR | Q27: Travis 2025 | R27: https://pmc.ncbi.nlm.nih.gov/articles/PMC12440227/
A28: U24 | B28: P15 | C28: BA | D28: Simoes Filho | E28: Baseline enrolment 2018-2020; median follow-up 41 months | F28: Children in dengue-vaccine trial cohort | G28: Baseline IgG | H28: 348 | I28: 23 | J28: =IF(OR(H28="",I28="",H28=0),"",I28/H28) -> 0.066091954 | K28: 0.07 | N28: RESTRICTED_POPULATION | O28: DIRECT n/N | P28: PEREIRA_PEDIATRIC | Q28: Pereira 2025 | R28: https://pmc.ncbi.nlm.nih.gov/articles/PMC12286324/
A29: U25 | B29: P16 | C29: CE | D29: Fortaleza endemic areas | E29: Baseline; cohort Feb 2018-Aug 2019; visit-specific range unverified | F29: Women, paired samples | G29: IgM or IgG (combined markers) | H29: 559 | I29: 190 | J29: =IF(OR(H29="",I29="",H29=0),"",I29/H29) -> 0.33989267 | K29: 0.34 | L29: 0.302 | M29: 0.38 | N29: RESTRICTED_POPULATION | O29: DIRECT n/N | P29: NOGUEIRA_FORTALEZA_PAIRED | Q29: Nogueira 2026 | R29: https://pubmed.ncbi.nlm.nih.gov/42525035/
A30: U26 | B30: P16 | C30: CE | D30: Fortaleza endemic areas | E30: First follow-up; cohort Feb 2018-Aug 2019; visit-specific range unverified | F30: Women, paired samples | G30: IgM or IgG (combined markers) | H30: 559 | I30: 175 | J30: =IF(OR(H30="",I30="",H30=0),"",I30/H30) -> 0.31305903 | K30: 0.313 | L30: 0.276 | M30: 0.353 | N30: RESTRICTED_POPULATION | O30: DIRECT n/N | P30: NOGUEIRA_FORTALEZA_PAIRED | Q30: Nogueira 2026 | R30: https://pubmed.ncbi.nlm.nih.gov/42525035/
A31: U27 | B31: P17 | C31: MG | D31: Diamantina | E31: 2018-2019 | F31: Asymptomatic pregnant women | G31: IgM only | H31: 135 | I31: 1 | J31: =IF(OR(H31="",I31="",H31=0),"",I31/H31) -> 0.0074074074 | K31: 0.007 | N31: RECENT_INFECTION_ONLY | O31: DIRECT n/N | P31: SANTOS_DIAMANTINA | Q31: Santos 2023 | R31: https://pubmed.ncbi.nlm.nih.gov/37454038/
A32: U28 | B32: P18 | C32: BA | D32: Salvador / IPERBA maternity hospital | E32: Collection dates not retrieved; publication 2023 is NOT sample date | F32: Immediate postpartum women | G32: IgG | H32: 302 | J32: =IF(OR(H32="",I32="",H32=0),"",I32/H32) | K32: 0.076 | N32: HOLD_MISSING_DATE | O32: Numerator NOT retrieved; do not reconstruct from rounded % | P32: BASTOS_IPERBA | Q32: Bastos Filho 2023 | R32: https://www.sciencedirect.com/science/article/pii/S2772707623000954
A33: U29 | B33: P19 | C33: SP | D33: Jundiai Zika Cohort / Jundiai | E33: March 2016-April 2021 | F33: High-risk pregnant women | G33: IgG reactive | H33: 526 | I33: 7 | J33: =IF(OR(H33="",I33="",H33=0),"",I33/H33) -> 0.013307985 | K33: 0.0133 | N33: RESTRICTED_POPULATION | O33: DIRECT n/N | P33: FAJARDO_JUNDIAI | Q33: Fajardo 2025 | R33: https://pubmed.ncbi.nlm.nih.gov/40638511/
A34: U30 | B34: P20 | C34: SP | D34: Vila Toninho, Sao Jose do Rio Preto | E34: Baseline: 2015-10 to 2016-03 | F34: Resident cohort complete-follow-up subset | G34: IgG | H34: 341 | I34: 1 | J34: =IF(OR(H34="",I34="",H34=0),"",I34/H34) -> 0.0029325513 | K34: 0.002 | L34: 0 | M34: 0.016 | N34: LOCAL_LONGITUDINAL | O34: DIRECT n/N | P34: ZINI_VILA_TONINHO_PAIRED | Q34: Zini 2024 | R34: https://journals.plos.org/plosntds/article?id=10.1371/journal.pntd.0012013
A35: U31 | B35: P20 | C35: SP | D35: Vila Toninho, Sao Jose do Rio Preto | E35: A01: 2016-10 to 2017-03 | F35: Resident cohort complete-follow-up subset | G35: IgG | H35: 341 | I35: 3 | J35: =IF(OR(H35="",I35="",H35=0),"",I35/H35) -> 0.008797654 | K35: 0.008 | L35: 0.003 | M35: 0.026 | N35: LOCAL_LONGITUDINAL | O35: DIRECT n/N | P35: ZINI_VILA_TONINHO_PAIRED | Q35: Zini 2024 | R35: https://journals.plos.org/plosntds/article?id=10.1371/journal.pntd.0012013
A36: U32 | B36: P20 | C36: SP | D36: Vila Toninho, Sao Jose do Rio Preto | E36: A02: 2017-10 to 2018-03 | F36: Resident cohort complete-follow-up subset | G36: IgG | H36: 341 | I36: 4 | J36: =IF(OR(H36="",I36="",H36=0),"",I36/H36) -> 0.011730205 | K36: 0.0117 | L36: 0.004 | M36: 0.03 | N36: LOCAL_LONGITUDINAL | O36: DIRECT n/N | P36: ZINI_VILA_TONINHO_PAIRED | Q36: Zini 2024 | R36: https://journals.plos.org/plosntds/article?id=10.1371/journal.pntd.0012013
A37: U33 | B37: P20 | C37: SP | D37: Vila Toninho, Sao Jose do Rio Preto | E37: A03: 2018-10 to 2019-03 | F37: Resident cohort complete-follow-up subset | G37: IgG | H37: 341 | I37: 8 | J37: =IF(OR(H37="",I37="",H37=0),"",I37/H37) -> 0.023460411 | K37: 0.0234 | L37: 0.011 | M37: 0.046 | N37: LOCAL_LONGITUDINAL | O37: DIRECT n/N | P37: ZINI_VILA_TONINHO_PAIRED | Q37: Zini 2024 | R37: https://journals.plos.org/plosntds/article?id=10.1371/journal.pntd.0012013
A38: U34 | B38: P20 | C38: SP | D38: Sao Jose do Rio Preto, dengue-suspected clinical panel | E38: 2019 | F38: Dengue-suspected patients | G38: IgM | H38: 497 | I38: 22 | J38: =IF(OR(H38="",I38="",H38=0),"",I38/H38) -> 0.044265594 | K38: 0.0442 | N38: EXCLUDE_CLINICAL_POSITIVITY | O38: DIRECT n/N | P38: ZINI_CLINICAL_2019 | Q38: Zini 2024 | R38: https://journals.plos.org/plosntds/article?id=10.1371/journal.pntd.0012013
A39: U35 | B39: P21 | C39: RJ | D39: HEMORIO blood centre, Rio de Janeiro | E39: 2019-2022 pooled | F39: Blood donations | G39: CHIKV prevalence; exact marker not recovered | H39: 778 | J39: =IF(OR(H39="",I39="",H39=0),"",I39/H39) | K39: 0.213 | N39: HOLD_ENDPOINT_DEFINITION | O39: Numerator NOT retrieved; do not reconstruct from rounded % | P39: SANTANNA_HEMORIO | Q39: Sant'Anna 2024 | R39: https://pubmed.ncbi.nlm.nih.gov/38970294/
A40: U36 | B40: P22 | C40: BA | D40: Saude | E40: 2021-2022 | F40: Town residents / field serum sample | G40: CHIKV IgG MIA | H40: 300 | I40: 17 | J40: =IF(OR(H40="",I40="",H40=0),"",I40/H40) -> 0.056666667 | K40: 0.057 | N40: LOCAL_CONTEXT | O40: DIRECT n/N | P40: WANG_SAUDE | Q40: Wang 2026 | R40: https://pmc.ncbi.nlm.nih.gov/articles/PMC13251372/

Sheet Raw_observations
A1: Raw observations
A2: Primary-source aggregate values only. Blank numerator means not retrieved. IgG/IgM alternatives and validation subsets overlap; never pool all rows.
A4: observation_id | B4: survey_id | C4: source_id | D4: uf | E4: place | F4: collection_dates | G4: endpoint | H4: n_tested | I4: n_positive | J4: raw_proportion | K4: reported_proportion | L4: reported_ci_low | M4: reported_ci_high | N4: reported_estimate_type | O4: assay | P4: preferred_endpoint_within_sample | Q4: raw_count_status | R4: verification_level | S4: source_locator | T4: source_url | U4: endpoint_overlap_note
A5: O001 | B5: U01 | C5: P01 | D5: BA | E5: Feira de Santana / George Americo | F5: Abstract: Oct-Dec 2015; methods: Nov-Dec 2015; table caption: 2015-2016 | G5: IgM or IgG | H5: 385 | I5: 220 | J5: =IF(OR(H5="",I5="",H5=0),"",I5/H5) -> 0.57142857 | K5: 0.571 | N5: Unweighted reported percentage | O5: Euroimmun ELISA IgM/IgG | P5: TRUE | Q5: DIRECT n/N | R5: PRIMARY_FULL_TEXT | S5: The Study; Table 1 | T5: https://wwwnc.cdc.gov/eid/article/24/4/17-1370_article
A6: O002 | B6: U01 | C6: P01 | D6: BA | E6: Feira de Santana / George Americo | F6: Abstract: Oct-Dec 2015; methods: Nov-Dec 2015; table caption: 2015-2016 | G6: IgG only | H6: 385 | I6: 163 | J6: =IF(OR(H6="",I6="",H6=0),"",I6/H6) -> 0.42337662 | N6: Unweighted reported percentage | O6: Euroimmun ELISA | P6: FALSE | Q6: DIRECT n/N | R6: PRIMARY_FULL_TEXT | S6: The Study | T6: https://wwwnc.cdc.gov/eid/article/24/4/17-1370_article | U6: Disjoint assay categories; total IgM-or-IgG endpoint already included.
A7: O003 | B7: U01 | C7: P01 | D7: BA | E7: Feira de Santana / George Americo | F7: Abstract: Oct-Dec 2015; methods: Nov-Dec 2015; table caption: 2015-2016 | G7: IgM only | H7: 385 | I7: 25 | J7: =IF(OR(H7="",I7="",H7=0),"",I7/H7) -> 0.064935065 | N7: Unweighted reported percentage | O7: Euroimmun ELISA | P7: FALSE | Q7: DIRECT n/N | R7: PRIMARY_FULL_TEXT | S7: The Study | T7: https://wwwnc.cdc.gov/eid/article/24/4/17-1370_article | U7: Disjoint assay categories; total IgM-or-IgG endpoint already included.
A8: O004 | B8: U01 | C8: P01 | D8: BA | E8: Feira de Santana / George Americo | F8: Abstract: Oct-Dec 2015; methods: Nov-Dec 2015; table caption: 2015-2016 | G8: IgG and IgM | H8: 385 | I8: 32 | J8: =IF(OR(H8="",I8="",H8=0),"",I8/H8) -> 0.083116883 | N8: Unweighted reported percentage | O8: Euroimmun ELISA | P8: FALSE | Q8: DIRECT n/N | R8: PRIMARY_FULL_TEXT | S8: The Study | T8: https://wwwnc.cdc.gov/eid/article/24/4/17-1370_article | U8: Disjoint assay categories; total IgM-or-IgG endpoint already included.
A9: O005 | B9: U02 | C9: P01 | D9: BA | E9: Riachao do Jacuipe / Alto do Cemiterio | F9: Abstract: Oct-Dec 2015; methods: Nov-Dec 2015; table caption: 2015-2016 | G9: IgM or IgG | H9: 446 | I9: 204 | J9: =IF(OR(H9="",I9="",H9=0),"",I9/H9) -> 0.4573991 | K9: 0.457 | N9: Unweighted reported percentage | O9: Euroimmun ELISA IgM/IgG | P9: TRUE | Q9: DIRECT n/N | R9: PRIMARY_FULL_TEXT | S9: The Study; Table 1 | T9: https://wwwnc.cdc.gov/eid/article/24/4/17-1370_article
A10: O006 | B10: U02 | C10: P01 | D10: BA | E10: Riachao do Jacuipe / Alto do Cemiterio | F10: Abstract: Oct-Dec 2015; methods: Nov-Dec 2015; table caption: 2015-2016 | G10: IgG only | H10: 446 | I10: 138 | J10: =IF(OR(H10="",I10="",H10=0),"",I10/H10) -> 0.30941704 | N10: Unweighted reported percentage | O10: Euroimmun ELISA | P10: FALSE | Q10: DIRECT n/N | R10: PRIMARY_FULL_TEXT | S10: The Study | T10: https://wwwnc.cdc.gov/eid/article/24/4/17-1370_article | U10: Disjoint assay categories; total IgM-or-IgG endpoint already included.
A11: O007 | B11: U02 | C11: P01 | D11: BA | E11: Riachao do Jacuipe / Alto do Cemiterio | F11: Abstract: Oct-Dec 2015; methods: Nov-Dec 2015; table caption: 2015-2016 | G11: IgM only | H11: 446 | I11: 38 | J11: =IF(OR(H11="",I11="",H11=0),"",I11/H11) -> 0.085201794 | N11: Unweighted reported percentage | O11: Euroimmun ELISA | P11: FALSE | Q11: DIRECT n/N | R11: PRIMARY_FULL_TEXT | S11: The Study | T11: https://wwwnc.cdc.gov/eid/article/24/4/17-1370_article | U11: Disjoint assay categories; total IgM-or-IgG endpoint already included.
A12: O008 | B12: U02 | C12: P01 | D12: BA | E12: Riachao do Jacuipe / Alto do Cemiterio | F12: Abstract: Oct-Dec 2015; methods: Nov-Dec 2015; table caption: 2015-2016 | G12: IgG and IgM | H12: 446 | I12: 28 | J12: =IF(OR(H12="",I12="",H12=0),"",I12/H12) -> 0.062780269 | N12: Unweighted reported percentage | O12: Euroimmun ELISA | P12: FALSE | Q12: DIRECT n/N | R12: PRIMARY_FULL_TEXT | S12: The Study | T12: https://wwwnc.cdc.gov/eid/article/24/4/17-1370_article | U12: Disjoint assay categories; total IgM-or-IgG endpoint already included.
A13: O009 | B13: U03 | C13: P02 | D13: BA | E13: Chapada rural district, Riachao do Jacuipe | F13: April 2016 | G13: IgM or IgG | H13: 120 | I13: 24 | J13: =IF(OR(H13="",I13="",H13=0),"",I13/H13) -> 0.2 | K13: 0.2 | L13: 0.154 | M13: 0.357 | N13: Unweighted reported percentage | O13: Euroimmun ELISA IgM/IgG | P13: TRUE | Q13: DIRECT n/N | R13: PRIMARY_FULL_TEXT | S13: Results | T13: https://journals.plos.org/plosntds/article?id=10.1371/journal.pntd.0005319 | U13: Reported CI retained verbatim numerically; unusually asymmetric for 24/120, verify with authors.
A14: O010 | B14: U03 | C14: P02 | D14: BA | E14: Chapada rural district, Riachao do Jacuipe | F14: April 2016 | G14: IgG positive (including dual positive) | H14: 120 | I14: 22 | J14: =IF(OR(H14="",I14="",H14=0),"",I14/H14) -> 0.18333333 | K14: 0.183 | N14: Unweighted reported percentage | O14: Euroimmun ELISA IgG | P14: FALSE | Q14: DIRECT n/N | R14: PRIMARY_FULL_TEXT | S14: Abstract / Results | T14: https://journals.plos.org/plosntds/article?id=10.1371/journal.pntd.0005319 | U14: Same sera; overlaps IgM-or-IgG endpoint.
A15: O011 | B15: U03 | C15: P02 | D15: BA | E15: Chapada rural district, Riachao do Jacuipe | F15: April 2016 | G15: IgM positive (including dual positive) | H15: 120 | I15: 6 | J15: =IF(OR(H15="",I15="",H15=0),"",I15/H15) -> 0.05 | K15: 0.05 | N15: Unweighted reported percentage | O15: Euroimmun ELISA IgM | P15: FALSE | Q15: DIRECT n/N | R15: PRIMARY_FULL_TEXT | S15: Abstract / Results | T15: https://journals.plos.org/plosntds/article?id=10.1371/journal.pntd.0005319 | U15: Same sera; four dual-positive specimens.
A16: O012 | B16: U03 | C16: P02 | D16: BA | E16: Chapada rural district, Riachao do Jacuipe | F16: April 2016 | G16: IgG and IgM | H16: 120 | I16: 4 | J16: =IF(OR(H16="",I16="",H16=0),"",I16/H16) -> 0.033333333 | N16: Unweighted reported percentage | O16: Euroimmun ELISA | P16: FALSE | Q16: DIRECT n/N | R16: PRIMARY_FULL_TEXT | S16: Abstract / Results | T16: https://journals.plos.org/plosntds/article?id=10.1371/journal.pntd.0005319 | U16: Subset of both IgG and IgM endpoints.
A17: O013 | B17: U04 | C17: P03 | D17: BA | E17: Pau da Lima, Salvador | F17: November 2016-February 2017 | G17: IgG | H17: 1772 | I17: 209 | J17: =IF(OR(H17="",I17="",H17=0),"",I17/H17) -> 0.11794582 | K17: 0.118 | L17: 0.098 | M17: 0.137 | N17: Household-adjusted confidence interval; reported prevalence | O17: Euroimmun IgG ELISA | P17: TRUE | Q17: DIRECT n/N | R17: PRIMARY_FULL_TEXT | S17: The Study / Results | T17: https://wwwnc.cdc.gov/eid/article/26/7/19-0846_article
A18: O014 | B18: U04 | C18: P03 | D18: BA | E18: Pau da Lima, Salvador | F18: November 2016-February 2017 | G18: IgM among IgG-positive participants only | H18: 209 | I18: 49 | J18: =IF(OR(H18="",I18="",H18=0),"",I18/H18) -> 0.23444976 | N18: Unweighted reported percentage | O18: InBios IgM ELISA | P18: FALSE | Q18: DIRECT n/N | R18: PRIMARY_FULL_TEXT | S18: Abstract / Results | T18: https://wwwnc.cdc.gov/eid/article/26/7/19-0846_article | U18: Conditional subset; NOT 49/1772 and not an independent serosurvey.
A19: O015 | B19: U05 | C19: P04 | D19: CE | E19: Juazeiro do Norte | F19: June-December 2018 | G19: IgM or IgG | H19: 404 | I19: 103 | J19: =IF(OR(H19="",I19="",H19=0),"",I19/H19) -> 0.2549505 | K19: 0.255 | N19: Unweighted reported percentage | O19: Euroimmun ELISA IgM/IgG | P19: TRUE | Q19: DIRECT n/N | R19: PRIMARY_FULL_TEXT | S19: Results / Abstract | T19: https://link.springer.com/article/10.1186/s12879-020-05611-5 | U19: Results 25.5%; abstract rounds to 25.0%. Raw 103/404 retained.
A20: O016 | B20: U06 | C20: P05 | D20: CE | E20: Quixada | F20: 2019 (title); exact months not recovered | G20: Anti-CHIKV exposure; marker combination not verified | H20: 409 | J20: =IF(OR(H20="",I20="",H20=0),"",I20/H20) | K20: 0.707 | N20: Unweighted reported percentage | O20: ELISA; isotype details not retrieved | P20: TRUE | Q20: Numerator NOT retrieved; do not reconstruct from rounded % | R20: PRIMARY_ABSTRACT | S20: Abstract | T20: https://onlinelibrary.wiley.com/doi/abs/10.1111/zph.12888 | U20: Do NOT convert 70.7% to 289 positives without source confirmation.
A21: O017 | B21: U07 | C21: P06 | D21: PE | E21: Fulni-o, Aguas Belas / Itaiba | F21: Aug 2016 and Jun 2017; pooled | G21: IgG | H21: 272 | I21: 213 | J21: =IF(OR(H21="",I21="",H21=0),"",I21/H21) -> 0.78308824 | K21: 0.783 | L21: 0.729 | M21: 0.831 | N21: Unweighted reported percentage | O21: Euroimmun IgG ELISA | P21: TRUE | Q21: DIRECT n/N | R21: PRIMARY_FULL_TEXT | S21: Results / Table 1 | T21: https://journals.plos.org/plosntds/article?id=10.1371/journal.pntd.0009468
A22: O018 | B22: U08 | C22: P06 | D22: PE | E22: Truka, Cabrobo | F22: June 2017 | G22: IgG | H22: 109 | I22: 0 | J22: =IF(OR(H22="",I22="",H22=0),"",I22/H22) -> 0 | K22: 0 | N22: Unweighted reported percentage | O22: Euroimmun IgG ELISA | P22: TRUE | Q22: DIRECT n/N | R22: PRIMARY_FULL_TEXT | S22: Results / Table 1 | T22: https://journals.plos.org/plosntds/article?id=10.1371/journal.pntd.0009468
A23: O019 | B23: U09 | C23: P06 | D23: BA | E23: Juazeiro urban non-Indigenous comparison | F23: June 2017 | G23: IgG | H23: 52 | I23: 3 | J23: =IF(OR(H23="",I23="",H23=0),"",I23/H23) -> 0.057692308 | K23: 0.058 | L23: 0.0121 | M23: 0.16 | N23: Unweighted reported percentage | O23: Euroimmun IgG ELISA | P23: TRUE | Q23: DIRECT n/N | R23: PRIMARY_FULL_TEXT | S23: Results / Table 1 | T23: https://journals.plos.org/plosntds/article?id=10.1371/journal.pntd.0009468
A24: O020 | B24: U10 | C24: P07 | D24: RJ | E24: Rio de Janeiro city | F24: July-October 2018 | G24: IgM or IgG | H24: 2120 | I24: 371 | J24: =IF(OR(H24="",I24="",H24=0),"",I24/H24) -> 0.175 | K24: 0.18 | L24: 0.148 | M24: 0.212 | N24: Survey-weighted prevalence and confidence interval | O24: Rapid IgM/IgG test; BahiaFarma | P24: TRUE | Q24: DIRECT n/N | R24: PRIMARY_FULL_TEXT | S24: Results / Discussion | T24: https://journals.plos.org/plosone/article?id=10.1371/journal.pone.0243239 | U24: Raw 371/2120 differs from weighted 18.0%; retain both.
A25: O021 | B25: U11 | C25: P08 | D25: AC | E25: Cruzeiro do Sul | F25: July 2015-June 2016 | G25: IgG | H25: 435 | I25: 41 | J25: =IF(OR(H25="",I25="",H25=0),"",I25/H25) -> 0.094252874 | K25: 0.094 | N25: Unweighted reported percentage | O25: Commercial ELISA; manufacturer not retrieved | P25: TRUE | Q25: DIRECT n/N | R25: PRIMARY_INDEXED_FULL_TEXT | S25: Abstract / Results | T25: https://pmc.ncbi.nlm.nih.gov/articles/PMC8993149/
A26: O022 | B26: U11 | C26: P08 | D26: AC | E26: Cruzeiro do Sul | F26: July 2015-June 2016 | G26: IgM | H26: 435 | I26: 0 | J26: =IF(OR(H26="",I26="",H26=0),"",I26/H26) -> 0 | K26: 0 | N26: Unweighted reported percentage | O26: Commercial ELISA | P26: FALSE | Q26: DIRECT n/N | R26: PRIMARY_INDEXED_FULL_TEXT | S26: Abstract / Results | T26: https://pmc.ncbi.nlm.nih.gov/articles/PMC8993149/ | U26: No IgM-positive samples; same participants.
A27: O023 | B27: U12 | C27: P08 | D27: AC | E27: Cruzeiro do Sul | F27: July 2015-June 2016 | G27: IgG | H27: 642 | I27: 66 | J27: =IF(OR(H27="",I27="",H27=0),"",I27/H27) -> 0.10280374 | K27: 0.103 | N27: Unweighted reported percentage | O27: Commercial ELISA; manufacturer not retrieved | P27: TRUE | Q27: DIRECT n/N | R27: PRIMARY_INDEXED_FULL_TEXT | S27: Abstract / Results | T27: https://pmc.ncbi.nlm.nih.gov/articles/PMC8993149/
A28: O024 | B28: U12 | C28: P08 | D28: AC | E28: Cruzeiro do Sul | F28: July 2015-June 2016 | G28: IgM | H28: 642 | I28: 0 | J28: =IF(OR(H28="",I28="",H28=0),"",I28/H28) -> 0 | K28: 0 | N28: Unweighted reported percentage | O28: Commercial ELISA | P28: FALSE | Q28: DIRECT n/N | R28: PRIMARY_INDEXED_FULL_TEXT | S28: Abstract / Results | T28: https://pmc.ncbi.nlm.nih.gov/articles/PMC8993149/ | U28: No IgM-positive samples; same participants.
A29: O025 | B29: U13 | C29: P09 | D29: BA | E29: Feira de Santana, 30 sentinel areas | F29: Apr-Sep 2017 in tables; 2016/2017 in abstract | G29: IgM or IgG | H29: 1981 | J29: =IF(OR(H29="",I29="",H29=0),"",I29/H29) | K29: 0.221 | L29: 0.167 | M29: 0.286 | N29: Population/sentinel-area estimate; no raw numerator recovered | O29: ELISA IgM/IgG; manufacturer not retrieved | P29: TRUE | Q29: Numerator NOT retrieved; do not reconstruct from rounded % | R29: PRIMARY_FULL_TEXT | S29: Results / Table 2 | T29: https://journals.plos.org/plosntds/article?id=10.1371/journal.pntd.0009289 | U29: Do not sum abstract component percentages; use reported overall estimate.
A30: O026 | B30: U14 | C30: P10 | D30: PE | E30: Recife | F30: August 2018-February 2019 | G30: IgM or IgG | H30: 2070 | I30: 770 | J30: =IF(OR(H30="",I30="",H30=0),"",I30/H30) -> 0.37198068 | K30: 0.372 | L30: 0.34 | M30: 0.404 | N30: Survey-weighted prevalence and confidence interval | O30: Euroimmun ELISA IgM/IgG | P30: TRUE | Q30: DIRECT n/N | R30: PRIMARY_FULL_TEXT | S30: Results | T30: https://journals.plos.org/plosntds/article?id=10.1371/journal.pntd.0011270
A31: O027 | B31: U14 | C31: P10 | D31: PE | E31: Recife | F31: August 2018-February 2019 | G31: IgG | H31: 2070 | J31: =IF(OR(H31="",I31="",H31=0),"",I31/H31) | K31: 0.357 | L31: 0.326 | M31: 0.389 | N31: Survey-weighted prevalence and confidence interval | O31: Euroimmun IgG ELISA | P31: FALSE | Q31: Numerator NOT retrieved; do not reconstruct from rounded % | R31: PRIMARY_FULL_TEXT | S31: Results | T31: https://journals.plos.org/plosntds/article?id=10.1371/journal.pntd.0011270 | U31: Same sera; no numerator reconstructed.
A32: O028 | B32: U14 | C32: P10 | D32: PE | E32: Recife | F32: August 2018-February 2019 | G32: IgM | H32: 2070 | J32: =IF(OR(H32="",I32="",H32=0),"",I32/H32) | K32: 0.035 | L32: 0.027 | M32: 0.042 | N32: Survey-weighted prevalence and confidence interval | O32: Euroimmun IgM ELISA | P32: FALSE | Q32: Numerator NOT retrieved; do not reconstruct from rounded % | R32: PRIMARY_FULL_TEXT | S32: Results | T32: https://journals.plos.org/plosntds/article?id=10.1371/journal.pntd.0011270 | U32: Same sera; not cumulative exposure alone.
A33: O029 | B33: U15 | C33: P11 | D33: DF | E33: Sao Sebastiao administrative region, Federal District | F33: Feb-Mar 2020 and Oct 2020-Jan 2021; pooled | G33: IgM or IgG | H33: 1405 | J33: =IF(OR(H33="",I33="",H33=0),"",I33/H33) | K33: 0.054 | L33: 0.044 | M33: 0.067 | N33: Reported overall seroprevalence | O33: IgM: Vircell / DiaPro; IgG: Euroimmun / Mobius (phase dependent) | P33: TRUE | Q33: Numerator NOT retrieved; do not reconstruct from rounded % | R33: PRIMARY_FULL_TEXT | S33: Abstract / Methods | T33: https://link.springer.com/article/10.1186/s12879-025-10516-2 | U33: Do not reconstruct 76 positives from rounded 5.4%.
A34: O030 | B34: U16 | C34: P12 | D34: AP | E34: Macapa / HEMOAP | F34: 2015 | G34: IgG | H34: 442 | I34: 1 | J34: =IF(OR(H34="",I34="",H34=0),"",I34/H34) -> 0.0022624434 | K34: 0.002 | N34: Unweighted reported percentage | O34: Anti-CHIKV IgG assay; platform/kit not retrieved | P34: TRUE | Q34: DIRECT n/N | R34: PRIMARY_ABSTRACT | S34: Abstract | T34: https://pubmed.ncbi.nlm.nih.gov/30370414/
A35: O031 | B35: U17 | C35: P12 | D35: SP | E35: Ribeirao Preto blood centre | F35: 2016 | G35: IgG | H35: 455 | I35: 0 | J35: =IF(OR(H35="",I35="",H35=0),"",I35/H35) -> 0 | K35: 0 | N35: Unweighted reported percentage | O35: Anti-CHIKV IgG assay; platform/kit not retrieved | P35: TRUE | Q35: DIRECT n/N | R35: PRIMARY_ABSTRACT | S35: Abstract | T35: https://pubmed.ncbi.nlm.nih.gov/30370414/
A36: O032 | B36: U18 | C36: P13 | D36: DF | E36: Federal District blood donors | F36: Early 2019 outbreak | G36: IgG | H36: 450 | I36: 4 | J36: =IF(OR(H36="",I36="",H36=0),"",I36/H36) -> 0.0088888889 | K36: 0.0089 | N36: Unweighted reported percentage | O36: ELISA; manufacturer not retrieved | P36: TRUE | Q36: DIRECT n/N | R36: PRIMARY_ABSTRACT | S36: Abstract | T36: https://onlinelibrary.wiley.com/doi/10.1111/tme.12870
A37: O033 | B37: U18 | C37: P13 | D37: DF | E37: Federal District blood donors | F37: Early 2019 outbreak | G37: IgM | H37: 450 | I37: 5 | J37: =IF(OR(H37="",I37="",H37=0),"",I37/H37) -> 0.011111111 | K37: 0.0111 | N37: Unweighted reported percentage | O37: ELISA; manufacturer not retrieved | P37: FALSE | Q37: DIRECT n/N | R37: PRIMARY_ABSTRACT | S37: Abstract | T37: https://onlinelibrary.wiley.com/doi/10.1111/tme.12870 | U37: IgG overlap not reported; do not add positive counts.
A38: O034 | B38: U19 | C38: P14 | D38: BA | E38: Alto do Cabrito, Salvador | F38: March-October 2018 | G38: IgG | H38: 376 | I38: 23 | J38: =IF(OR(H38="",I38="",H38=0),"",I38/H38) -> 0.061170213 | K38: 0.061 | N38: Unweighted reported percentage | O38: IgG ELISA; kit not retrieved | P38: TRUE | Q38: DIRECT n/N | R38: PRIMARY_INDEXED_FULL_TEXT | S38: Results / Table 1 | T38: https://pmc.ncbi.nlm.nih.gov/articles/PMC12440227/
A39: O035 | B39: U20 | C39: P14 | D39: BA | E39: Marechal Rondon, Salvador | F39: March-October 2018 | G39: IgG | H39: 337 | I39: 16 | J39: =IF(OR(H39="",I39="",H39=0),"",I39/H39) -> 0.047477745 | K39: 0.048 | N39: Unweighted reported percentage | O39: IgG ELISA; kit not retrieved | P39: TRUE | Q39: DIRECT n/N | R39: PRIMARY_INDEXED_FULL_TEXT | S39: Results / Table 1 | T39: https://pmc.ncbi.nlm.nih.gov/articles/PMC12440227/
A40: O036 | B40: U21 | C40: P14 | D40: BA | E40: Nova Constituinte, Salvador | F40: March-October 2018 | G40: IgG | H40: 305 | I40: 69 | J40: =IF(OR(H40="",I40="",H40=0),"",I40/H40) -> 0.22622951 | K40: 0.226 | N40: Unweighted reported percentage | O40: IgG ELISA; kit not retrieved | P40: TRUE | Q40: DIRECT n/N | R40: PRIMARY_INDEXED_FULL_TEXT | S40: Results / Table 1 | T40: https://pmc.ncbi.nlm.nih.gov/articles/PMC12440227/
A41: O037 | B41: U22 | C41: P14 | D41: BA | E41: Rio Sena, Salvador | F41: March-October 2018 | G41: IgG | H41: 298 | I41: 13 | J41: =IF(OR(H41="",I41="",H41=0),"",I41/H41) -> 0.043624161 | K41: 0.043 | N41: Unweighted reported percentage | O41: IgG ELISA; kit not retrieved | P41: TRUE | Q41: DIRECT n/N | R41: PRIMARY_INDEXED_FULL_TEXT | S41: Results / Table 1 | T41: https://pmc.ncbi.nlm.nih.gov/articles/PMC12440227/
...

Sheet Survey_units
A1: Survey units
A2: Geographic/time metadata and eligibility cautions. Collection dates are not publication dates. No observation is assumed representative of an entire UF.
A4: survey_id | B4: source_id | C4: uf | D4: place | E4: collection_start | F4: collection_end | G4: date_precision | H4: collection_dates_as_reported | I4: population | J4: age_range | K4: sampling_design | L4: representativeness | M4: cohort_or_overlap_id | N4: suggested_role | O4: upstream_foi_overlap | P4: limitations | Q4: source_url
A5: U01 | B5: P01 | C5: BA | D5: Feira de Santana / George Americo | E5: 2015-10 | F5: 2015-12 | G5: MONTH_CONFLICT | H5: Abstract: Oct-Dec 2015; methods: Nov-Dec 2015; table caption: 2015-2016 | I5: Residents of selected epidemic hotspots | J5: >1 year; residence >6 months | K5: Five high-incidence census tracts; one participant sampled per household | L5: Hotspot neighbourhoods; NOT municipality-wide | M5: DIAS_2015_U01 | N5: LOCAL_CONTEXT | O5: Unknown; audit original FOI training data | P5: Collection-date descriptions differ within source; confirm exact range. | Q5: https://wwwnc.cdc.gov/eid/article/24/4/17-1370_article
A6: U02 | B6: P01 | C6: BA | D6: Riachao do Jacuipe / Alto do Cemiterio | E6: 2015-10 | F6: 2015-12 | G6: MONTH_CONFLICT | H6: Abstract: Oct-Dec 2015; methods: Nov-Dec 2015; table caption: 2015-2016 | I6: Residents of selected epidemic hotspots | J6: >1 year; residence >6 months | K6: Five high-incidence census tracts; one participant sampled per household | L6: Hotspot neighbourhoods; NOT municipality-wide | M6: DIAS_2015_U02 | N6: LOCAL_CONTEXT | O6: Unknown; audit original FOI training data | P6: Collection-date descriptions differ within source; confirm exact range. | Q6: https://wwwnc.cdc.gov/eid/article/24/4/17-1370_article
A7: U03 | B7: P02 | C7: BA | D7: Chapada rural district, Riachao do Jacuipe | E7: 2016-04 | F7: 2016-04 | G7: MONTH | H7: April 2016 | I7: Rural residents | J7: Mean 36.6 years (SD 20.9) | K7: 45 households selected from 505; 120 of 160 invited participated | L7: Rural district; not the urban hotspot in P01 | M7: CUNHA_CHAPADA | N7: LOCAL_POPULATION_PRIORITY | O7: Unknown; audit original FOI training data | Q7: https://journals.plos.org/plosntds/article?id=10.1371/journal.pntd.0005319
A8: U04 | B8: P03 | C8: BA | D8: Pau da Lima, Salvador | E8: 2016-11 | F8: 2017-02 | G8: MONTH | H8: November 2016-February 2017 | I8: Residents in three contiguous valleys | J8: >=5 years | K8: Household serosurvey | L8: Selected urban informal settlement, not Salvador city | M8: ANJOS_PAU_DA_LIMA | N8: LOCAL_CONTEXT | O8: Unknown; audit original FOI training data | P8: 1,776 enrolled; 1,772 IgG results. | Q8: https://wwwnc.cdc.gov/eid/article/26/7/19-0846_article
A9: U05 | B9: P04 | C9: CE | D9: Juazeiro do Norte | E9: 2018-06 | F9: 2018-12 | G9: MONTH | H9: June-December 2018 | I9: Urban household residents | J9: All household members invited; exact lower age not retrieved | K9: Random geographic points allocated across neighbourhoods; nearest household | L9: Municipality urban household sample; not Ceara-wide | M9: BARRETO_JUAZEIRO | N9: LOCAL_POPULATION_PRIORITY | O9: Already used in user FOI work / existing anchor | P9: Household selection and nonresponse need design-aware analysis. | Q9: https://link.springer.com/article/10.1186/s12879-020-05611-5
A10: U06 | B10: P05 | C10: CE | D10: Quixada | E10: 2019 | F10: 2019 | G10: YEAR_ONLY | H10: 2019 (title); exact months not recovered | I10: Endemic-area residents | J10: Not retrieved | K10: Cross-sectional seroepidemiological survey; full sampling frame not retrieved | L10: Local survey; municipality representativeness needs verification | M10: BRAGA_QUIXADA | N10: LOCAL_CONTEXT | O10: Already used in user FOI work / existing anchor | P10: Do not reuse previously assumed 2018-2019 dates without original methods. | Q10: https://onlinelibrary.wiley.com/doi/abs/10.1111/zph.12888
A11: U07 | B11: P06 | C11: PE | D11: Fulni-o, Aguas Belas / Itaiba | E11: 2016-08 | F11: 2017-06 | G11: DISCONTINUOUS | H11: Aug 2016 and Jun 2017; pooled | I11: PAI cardiovascular cohort adults | J11: 30-70 years | K11: Cohort-selected Indigenous / urban comparison groups | L11: Restricted age/community cohort; NOT state representative | M11: NICACIO_U07 | N11: LOCAL_CONTEXT | O11: Unknown; audit original FOI training data | P11: Cardiovascular/renal exclusions; Fulni-o pooled collection rounds not separable. | Q11: https://journals.plos.org/plosntds/article?id=10.1371/journal.pntd.0009468
A12: U08 | B12: P06 | C12: PE | D12: Truka, Cabrobo | E12: 2017-06 | F12: 2017-06 | G12: MONTH | H12: June 2017 | I12: PAI cardiovascular cohort adults | J12: 30-70 years | K12: Cohort-selected Indigenous / urban comparison groups | L12: Restricted age/community cohort; NOT state representative | M12: NICACIO_U08 | N12: LOCAL_CONTEXT | O12: Unknown; audit original FOI training data | P12: Cardiovascular/renal exclusions; Fulni-o pooled collection rounds not separable. | Q12: https://journals.plos.org/plosntds/article?id=10.1371/journal.pntd.0009468
A13: U09 | B13: P06 | C13: BA | D13: Juazeiro urban non-Indigenous comparison | E13: 2017-06 | F13: 2017-06 | G13: MONTH | H13: June 2017 | I13: PAI cardiovascular cohort adults | J13: 30-70 years | K13: Cohort-selected Indigenous / urban comparison groups | L13: Restricted age/community cohort; NOT state representative | M13: NICACIO_U09 | N13: LOCAL_CONTEXT | O13: Unknown; audit original FOI training data | P13: Cardiovascular/renal exclusions; Fulni-o pooled collection rounds not separable. | Q13: https://journals.plos.org/plosntds/article?id=10.1371/journal.pntd.0009468
A14: U10 | B14: P07 | C14: RJ | D14: Rio de Janeiro city | E14: 2018-07 | F14: 2018-10 | G14: MONTH | H14: July-October 2018 | I14: City residents | J14: All ages; see original age strata | K14: Administrative-region stratified household survey; design/nonresponse weights | L14: City population-based; NOT Rio de Janeiro state | M14: PERISSE_RIO | N14: LOCAL_POPULATION_PRIORITY | O14: Unknown; audit original FOI training data | Q14: https://journals.plos.org/plosone/article?id=10.1371/journal.pone.0243239
A15: U11 | B15: P08 | C15: AC | D15: Cruzeiro do Sul | E15: 2015-07 | F15: 2016-06 | G15: MONTH | H15: July 2015-June 2016 | I15: Pregnant women | J15: Pregnant women; age range not retrieved | K15: MINA cohort / antenatal units | L15: Maternal/infant cohort; not general population | M15: KANUNFRE_U11 | N15: RESTRICTED_POPULATION | O15: Unknown; audit original FOI training data | Q15: https://pmc.ncbi.nlm.nih.gov/articles/PMC8993149/
A16: U12 | B16: P08 | C16: AC | D16: Cruzeiro do Sul | E16: 2015-07 | F16: 2016-06 | G16: MONTH | H16: July 2015-June 2016 | I16: Unrelated newborns | J16: Newborn | K16: MINA cohort / antenatal units | L16: Maternal/infant cohort; not general population | M16: KANUNFRE_U12 | N16: EXCLUDE_INFANT_INFECTION | O16: Unknown; audit original FOI training data | P16: Newborn IgG can reflect maternal antibodies; cannot anchor infant infection burden. | Q16: https://pmc.ncbi.nlm.nih.gov/articles/PMC8993149/
A17: U13 | B17: P09 | C17: BA | D17: Feira de Santana, 30 sentinel areas | E17: 2017-04 | F17: 2017-09 | G17: MONTH_CONFLICT | H17: Apr-Sep 2017 in tables; 2016/2017 in abstract | I17: Urban residents across living-condition strata | J17: All ages; exact minimum not retrieved | K17: Random sample in 30 sentinel areas across living-condition strata | L17: Broad city sample with sentinel-area design; NOT state representative | M17: TEIXEIRA_FEIRA | N17: LOCAL_POPULATION_PRIORITY | O17: Unknown; audit original FOI training data | P17: Do not treat as same survey as P01 hotspot; dates and sampling differ. | Q17: https://journals.plos.org/plosntds/article?id=10.1371/journal.pntd.0009289
A18: U14 | B18: P10 | C18: PE | D18: Recife | E18: 2018-08 | F18: 2019-02 | G18: MONTH | H18: August 2018-February 2019 | I18: Household residents | J18: 5-65 years | K18: Stratified random household survey by socioeconomic level | L18: City population-based; NOT Pernambuco-wide | M18: BRAGA_RECIFE | N18: LOCAL_POPULATION_PRIORITY | O18: Unknown; audit original FOI training data | Q18: https://journals.plos.org/plosntds/article?id=10.1371/journal.pntd.0011270
A19: U15 | B19: P11 | C19: DF | D19: Sao Sebastiao administrative region, Federal District | E19: 2020-02 | F19: 2021-01 | G19: DISCONTINUOUS | H19: Feb-Mar 2020 and Oct 2020-Jan 2021; pooled | I19: Residents sampled from households | J19: Invited >=5 years; results describe ages 18-87; verify | K19: Random household survey in two pandemic-separated phases | L19: Administrative region, including area later Jardin Botanico; NOT entire DF | M19: NOBRE_DF | N19: LOCAL_POPULATION_PRIORITY | O19: Unknown; audit original FOI training data | P19: Assay brands changed between phases; exact age frame and numerator need verification. | Q19: https://link.springer.com/article/10.1186/s12879-025-10516-2
A20: U16 | B20: P12 | C20: AP | D20: Macapa / HEMOAP | E20: 2015 | F20: 2015 | G20: YEAR_ONLY | H20: 2015 | I20: Volunteer blood donors | J20: Donation-eligible; exact ages not retrieved | K20: Blood donation sample | L20: Healthy donor population only | M20: SLAVOV_U16 | N20: RESTRICTED_POPULATION | O20: Unknown; audit original FOI training data | Q20: https://pubmed.ncbi.nlm.nih.gov/30370414/
A21: U17 | B21: P12 | C21: SP | D21: Ribeirao Preto blood centre | E21: 2016 | F21: 2016 | G21: YEAR_ONLY | H21: 2016 | I21: Volunteer blood donors | J21: Donation-eligible; exact ages not retrieved | K21: Blood donation sample | L21: Healthy donor population only | M21: SLAVOV_U17 | N21: RESTRICTED_POPULATION | O21: Unknown; audit original FOI training data | Q21: https://pubmed.ncbi.nlm.nih.gov/30370414/
A22: U18 | B22: P13 | C22: DF | D22: Federal District blood donors | E22: 2019 | F22: 2019 | G22: YEAR_QUALIFIED | H22: Early 2019 outbreak | I22: Volunteer blood donors | J22: Donation-eligible; exact ages not retrieved | K22: 450 volunteer donations | L22: Donor population only | M22: MENDES_DF | N22: RESTRICTED_POPULATION | O22: Unknown; audit original FOI training data | Q22: https://onlinelibrary.wiley.com/doi/10.1111/tme.12870
A23: U19 | B23: P14 | C23: BA | D23: Alto do Cabrito, Salvador | E23: 2018-03 | F23: 2018-10 | G23: MONTH | H23: March-October 2018 | I23: Residents in four informal settlements | J23: >=5 years; resident >=6 months | K23: Community census / household recruitment | L23: Selected neighbourhoods only | M23: TRAVIS_SALVADOR | N23: LOCAL_CONTEXT | O23: Unknown; audit original FOI training data | P23: Pooled U23 duplicates U19-U22; 1,318 samples, 1,316 conclusive IgG results. | Q23: https://pmc.ncbi.nlm.nih.gov/articles/PMC12440227/
A24: U20 | B24: P14 | C24: BA | D24: Marechal Rondon, Salvador | E24: 2018-03 | F24: 2018-10 | G24: MONTH | H24: March-October 2018 | I24: Residents in four informal settlements | J24: >=5 years; resident >=6 months | K24: Community census / household recruitment | L24: Selected neighbourhoods only | M24: TRAVIS_SALVADOR | N24: LOCAL_CONTEXT | O24: Unknown; audit original FOI training data | P24: Pooled U23 duplicates U19-U22; 1,318 samples, 1,316 conclusive IgG results. | Q24: https://pmc.ncbi.nlm.nih.gov/articles/PMC12440227/
A25: U21 | B25: P14 | C25: BA | D25: Nova Constituinte, Salvador | E25: 2018-03 | F25: 2018-10 | G25: MONTH | H25: March-October 2018 | I25: Residents in four informal settlements | J25: >=5 years; resident >=6 months | K25: Community census / household recruitment | L25: Selected neighbourhoods only | M25: TRAVIS_SALVADOR | N25: LOCAL_CONTEXT | O25: Unknown; audit original FOI training data | P25: Pooled U23 duplicates U19-U22; 1,318 samples, 1,316 conclusive IgG results. | Q25: https://pmc.ncbi.nlm.nih.gov/articles/PMC12440227/
A26: U22 | B26: P14 | C26: BA | D26: Rio Sena, Salvador | E26: 2018-03 | F26: 2018-10 | G26: MONTH | H26: March-October 2018 | I26: Residents in four informal settlements | J26: >=5 years; resident >=6 months | K26: Community census / household recruitment | L26: Selected neighbourhoods only | M26: TRAVIS_SALVADOR | N26: LOCAL_CONTEXT | O26: Unknown; audit original FOI training data | P26: Pooled U23 duplicates U19-U22; 1,318 samples, 1,316 conclusive IgG results. | Q26: https://pmc.ncbi.nlm.nih.gov/articles/PMC12440227/
A27: U23 | B27: P14 | C27: BA | D27: Four Salvador communities pooled | E27: 2018-03 | F27: 2018-10 | G27: MONTH | H27: March-October 2018 | I27: Residents in four informal settlements | J27: >=5 years; resident >=6 months | K27: Community census / household recruitment | L27: Selected neighbourhoods only | M27: TRAVIS_SALVADOR | N27: POOLED_DUPLICATE | O27: Unknown; audit original FOI training data | P27: Pooled U23 duplicates U19-U22; 1,318 samples, 1,316 conclusive IgG results. | Q27: https://pmc.ncbi.nlm.nih.gov/articles/PMC12440227/
A28: U24 | B28: P15 | C28: BA | D28: Simoes Filho | E28: 2018 | F28: 2020 | G28: ENROLMENT_WINDOW | H28: Baseline enrolment 2018-2020; median follow-up 41 months | I28: Children in dengue-vaccine trial cohort | J28: 2-17 years | K28: Nested prospective pediatric cohort; baseline serology | L28: Pediatric trial cohort only | M28: PEREIRA_PEDIATRIC | N28: RESTRICTED_POPULATION | O28: Unknown; audit original FOI training data | P28: 23 baseline positive; do not treat 53 incident mixed-diagnostic infections as endpoint seroprevalence. | Q28: https://pmc.ncbi.nlm.nih.gov/articles/PMC12286324/
A29: U25 | B29: P16 | C29: CE | D29: Fortaleza endemic areas | E29: 2018-02 | F29: 2019-08 | G29: COHORT_WINDOW_NOT_VISIT_DATE | H29: Baseline; cohort Feb 2018-Aug 2019; visit-specific range unverified | I29: Women, paired samples | J29: 15-39 years | K29: Longitudinal female cohort after 2017 outbreak | L29: Women in endemic areas, NOT all Fortaleza residents | M29: NOGUEIRA_FORTALEZA_PAIRED | N29: RESTRICTED_POPULATION | O29: Unknown; audit original FOI training data | P29: Same 559 women at two visits; do not treat visits as independent. | Q29: https://pubmed.ncbi.nlm.nih.gov/42525035/
A30: U26 | B30: P16 | C30: CE | D30: Fortaleza endemic areas | E30: 2018-02 | F30: 2019-08 | G30: COHORT_WINDOW_NOT_VISIT_DATE | H30: First follow-up; cohort Feb 2018-Aug 2019; visit-specific range unverified | I30: Women, paired samples | J30: 15-39 years | K30: Longitudinal female cohort after 2017 outbreak | L30: Women in endemic areas, NOT all Fortaleza residents | M30: NOGUEIRA_FORTALEZA_PAIRED | N30: RESTRICTED_POPULATION | O30: Unknown; audit original FOI training data | P30: Same 559 women at two visits; do not treat visits as independent. | Q30: https://pubmed.ncbi.nlm.nih.gov/42525035/
A31: U27 | B31: P17 | C31: MG | D31: Diamantina | E31: 2018 | F31: 2019 | G31: YEAR_RANGE | H31: 2018-2019 | I31: Asymptomatic pregnant women | J31: Adult pregnant cohort; range not retrieved | K31: Antenatal cohort | L31: Restricted pregnancy sample; IgM only | M31: SANTOS_DIAMANTINA | N31: RECENT_INFECTION_ONLY | O31: Unknown; audit original FOI training data | Q31: https://pubmed.ncbi.nlm.nih.gov/37454038/
A32: U28 | B32: P18 | C32: BA | D32: Salvador / IPERBA maternity hospital | G32: NOT_RETRIEVED | H32: Collection dates not retrieved; publication 2023 is NOT sample date | I32: Immediate postpartum women | J32: Median 26 years; IQR 21-33 | K32: Hospital cross-sectional maternity sample | L32: Hospital-selected women only | M32: BASTOS_IPERBA | N32: HOLD_MISSING_DATE | O32: Unknown; audit original FOI training data | Q32: https://www.sciencedirect.com/science/article/pii/S2772707623000954
A33: U29 | B33: P19 | C33: SP | D33: Jundiai Zika Cohort / Jundiai | E33: 2016-03 | F33: 2021-04 | G33: MONTH | H33: March 2016-April 2021 | I33: High-risk pregnant women | J33: Range not retrieved | K33: Clinical pregnancy cohort | L33: High-risk pregnancy sample; recruitment catchment needs confirmation | M33: FAJARDO_JUNDIAI | N33: RESTRICTED_POPULATION | O33: Unknown; audit original FOI training data | P33: No year-disaggregated data recovered; Jundiai identified through named cohort and affiliations. | Q33: https://pubmed.ncbi.nlm.nih.gov/40638511/
A34: U30 | B34: P20 | C34: SP | D34: Vila Toninho, Sao Jose do Rio Preto | E34: 2015-10 | F34: 2016-03 | G34: MONTH | H34: Baseline: 2015-10 to 2016-03 | I34: Resident cohort complete-follow-up subset | J34: >=10 years | K34: 1,517 enrolled; 341 completed all four visits | L34: Neighbourhood cohort; strong complete-case selection | M34: ZINI_VILA_TONINHO_PAIRED | N34: LOCAL_LONGITUDINAL | O34: Unknown; audit original FOI training data | P34: Same persons across visits; source rounding differs from raw fractions. | Q34: https://journals.plos.org/plosntds/article?id=10.1371/journal.pntd.0012013
A35: U31 | B35: P20 | C35: SP | D35: Vila Toninho, Sao Jose do Rio Preto | E35: 2016-10 | F35: 2017-03 | G35: MONTH | H35: A01: 2016-10 to 2017-03 | I35: Resident cohort complete-follow-up subset | J35: >=10 years | K35: 1,517 enrolled; 341 completed all four visits | L35: Neighbourhood cohort; strong complete-case selection | M35: ZINI_VILA_TONINHO_PAIRED | N35: LOCAL_LONGITUDINAL | O35: Unknown; audit original FOI training data | P35: Same persons across visits; source rounding differs from raw fractions. | Q35: https://journals.plos.org/plosntds/article?id=10.1371/journal.pntd.0012013
A36: U32 | B36: P20 | C36: SP | D36: Vila Toninho, Sao Jose do Rio Preto | E36: 2017-10 | F36: 2018-03 | G36: MONTH | H36: A02: 2017-10 to 2018-03 | I36: Resident cohort complete-follow-up subset | J36: >=10 years | K36: 1,517 enrolled; 341 completed all four visits | L36: Neighbourhood cohort; strong complete-case selection | M36: ZINI_VILA_TONINHO_PAIRED | N36: LOCAL_LONGITUDINAL | O36: Unknown; audit original FOI training data | P36: Same persons across visits; source rounding differs from raw fractions. | Q36: https://journals.plos.org/plosntds/article?id=10.1371/journal.pntd.0012013
A37: U33 | B37: P20 | C37: SP | D37: Vila Toninho, Sao Jose do Rio Preto | E37: 2018-10 | F37: 2019-03 | G37: MONTH | H37: A03: 2018-10 to 2019-03 | I37: Resident cohort complete-follow-up subset | J37: >=10 years | K37: 1,517 enrolled; 341 completed all four visits | L37: Neighbourhood cohort; strong complete-case selection | M37: ZINI_VILA_TONINHO_PAIRED | N37: LOCAL_LONGITUDINAL | O37: Unknown; audit original FOI training data | P37: Same persons across visits; source rounding differs from raw fractions. | Q37: https://journals.plos.org/plosntds/article?id=10.1371/journal.pntd.0012013
A38: U34 | B38: P20 | C38: SP | D38: Sao Jose do Rio Preto, dengue-suspected clinical panel | E38: 2019 | F38: 2019 | G38: YEAR_ONLY | H38: 2019 | I38: Dengue-suspected patients | J38: Not retrieved | K38: Separate clinical diagnostic panel | L38: Clinical test positivity, not community prevalence | M38: ZINI_CLINICAL_2019 | N38: EXCLUDE_CLINICAL_POSITIVITY | O38: Unknown; audit original FOI training data | Q38: https://journals.plos.org/plosntds/article?id=10.1371/journal.pntd.0012013
A39: U35 | B39: P21 | C39: RJ | D39: HEMORIO blood centre, Rio de Janeiro | E39: 2019 | F39: 2022 | G39: YEAR_RANGE | H39: 2019-2022 pooled | I39: Blood donations | J39: Donation-eligible; range not retrieved | K39: Serological/molecular screening of donations | L39: Donor sample only; pooled over four years | M39: SANTANNA_HEMORIO | N39: HOLD_ENDPOINT_DEFINITION | O39: Unknown; audit original FOI training data | Q39: https://pubmed.ncbi.nlm.nih.gov/38970294/
A40: U36 | B40: P22 | C40: BA | D40: Saude | E40: 2021 | F40: 2022 | G40: YEAR_RANGE | H40: 2021-2022 | I40: Town residents / field serum sample | J40: 11-91 years; mean 42.1 | K40: 300 field sera; exact probability-sampling frame not retrieved | L40: Local sample; not established town-representative | M40: WANG_SAUDE | N40: LOCAL_CONTEXT | O40: Unknown; audit original FOI training data | P40: 16/17 CHIKV-MIA-positive sera had enough volume for neutralization; all 16 confirmed. | Q40: https://pmc.ncbi.nlm.nih.gov/articles/PMC13251372/

Sheet Age_strata
A1: Age strata
A2: Only directly recovered age-specific counts. Nested in parent samples; not additional independent observations. Original age labels retained.
A4: stratum_id | B4: survey_id | C4: source_id | D4: uf | E4: age_group_as_reported | F4: n_tested | G4: n_positive | H4: raw_proportion | I4: reported_proportion | J4: source_locator | K4: source_url | L4: notes
A5: A001 | B5: U01 | C5: P01 | D5: BA | E5: 1-19 | F5: 88 | G5: 46 | H5: =IF(OR(F5="",G5="",F5=0),"",G5/F5) -> 0.52272727 | J5: Table 1 | K5: https://wwwnc.cdc.gov/eid/article/24/4/17-1370_article | L5: Preserve age label >60 as printed.
A6: A002 | B6: U01 | C6: P01 | D6: BA | E6: 20-39 | F6: 123 | G6: 72 | H6: =IF(OR(F6="",G6="",F6=0),"",G6/F6) -> 0.58536585 | J6: Table 1 | K6: https://wwwnc.cdc.gov/eid/article/24/4/17-1370_article | L6: Preserve age label >60 as printed.
A7: A003 | B7: U01 | C7: P01 | D7: BA | E7: 40-59 | F7: 121 | G7: 69 | H7: =IF(OR(F7="",G7="",F7=0),"",G7/F7) -> 0.57024793 | J7: Table 1 | K7: https://wwwnc.cdc.gov/eid/article/24/4/17-1370_article | L7: Preserve age label >60 as printed.
A8: A004 | B8: U01 | C8: P01 | D8: BA | E8: >60 | F8: 53 | G8: 33 | H8: =IF(OR(F8="",G8="",F8=0),"",G8/F8) -> 0.62264151 | J8: Table 1 | K8: https://wwwnc.cdc.gov/eid/article/24/4/17-1370_article | L8: Preserve age label >60 as printed.
A9: A005 | B9: U02 | C9: P01 | D9: BA | E9: 1-19 | F9: 45 | G9: 17 | H9: =IF(OR(F9="",G9="",F9=0),"",G9/F9) -> 0.37777778 | J9: Table 1 | K9: https://wwwnc.cdc.gov/eid/article/24/4/17-1370_article | L9: Preserve age label >60 as printed.
A10: A006 | B10: U02 | C10: P01 | D10: BA | E10: 20-39 | F10: 109 | G10: 55 | H10: =IF(OR(F10="",G10="",F10=0),"",G10/F10) -> 0.50458716 | J10: Table 1 | K10: https://wwwnc.cdc.gov/eid/article/24/4/17-1370_article | L10: Preserve age label >60 as printed.
A11: A007 | B11: U02 | C11: P01 | D11: BA | E11: 40-59 | F11: 144 | G11: 63 | H11: =IF(OR(F11="",G11="",F11=0),"",G11/F11) -> 0.4375 | J11: Table 1 | K11: https://wwwnc.cdc.gov/eid/article/24/4/17-1370_article | L11: Preserve age label >60 as printed.
A12: A008 | B12: U02 | C12: P01 | D12: BA | E12: >60 | F12: 148 | G12: 69 | H12: =IF(OR(F12="",G12="",F12=0),"",G12/F12) -> 0.46621622 | J12: Table 1 | K12: https://wwwnc.cdc.gov/eid/article/24/4/17-1370_article | L12: Preserve age label >60 as printed.
A13: A009 | B13: U23 | C13: P14 | D13: BA | E13: 5-15 | F13: 233 | G13: 22 | H13: =IF(OR(F13="",G13="",F13=0),"",G13/F13) -> 0.094420601 | J13: Table 1 | K13: https://pmc.ncbi.nlm.nih.gov/articles/PMC12440227/ | L13: Pooled four communities; age denominators sum to 1,307, not 1,316. Preserve source >66 label.
A14: A010 | B14: U23 | C14: P14 | D14: BA | E14: 16-25 | F14: 262 | G14: 30 | H14: =IF(OR(F14="",G14="",F14=0),"",G14/F14) -> 0.11450382 | J14: Table 1 | K14: https://pmc.ncbi.nlm.nih.gov/articles/PMC12440227/ | L14: Pooled four communities; age denominators sum to 1,307, not 1,316. Preserve source >66 label.
